<?xml version="1.0"?>
<!-- created with Phobos 0.7 -->
  <robot name="stick_insect">

    <link name="leg11">
    </link>

    <link name="leg12">
      <inertial>
        <origin xyz="0.15 0 0" rpy="0 0 0"/>
        <mass value="0.5"/>
        <inertia ixx="0.00024" ixy="-3e-05" ixz="4e-05" iyy="0.00514" iyz="0" izz="0.00515"/>
      </inertial>
      <visual name="visual_leg1_upper">
        <origin xyz="0.15 0 0" rpy="-1.5708 0 0"/>
        <geometry>
          <mesh filename="../meshes/obj/upper_leg.obj" scale="1.0 1.0 1.0"/>
        </geometry>
        <material name="upper_leg"/>
      </visual>
      <collision name="collision_leg1_upper">
        <origin xyz="0.12867 0 0" rpy="-1.5708 0 0"/>
        <geometry>
          <box size="0.23617 0.06 0.06"/>
        </geometry>
      </collision>
    </link>

    <link name="leg13">
      <inertial>
        <origin xyz="0.16667 0 -0.00847" rpy="0 0 0"/>
        <mass value="0.6"/>
        <inertia ixx="0.00052" ixy="0" ixz="-0.00085" iyy="0.01026" iyz="0" izz="0.01004"/>
      </inertial>
      <visual name="visual_leg1_foot">
        <origin xyz="0.4 0 0" rpy="-1.5708 0 1.5708"/>
        <geometry>
          <mesh filename="../meshes/obj/foot.obj" scale="1.0 1.0 1.0"/>
        </geometry>
        <material name="body"/>
      </visual>
      <visual name="visual_leg1_knee">
        <origin xyz="5e-05 2e-05 -0.05082" rpy="1.5708 0 -1.5708"/>
        <geometry>
          <mesh filename="../meshes/obj/knee.obj" scale="1.0 1.0 1.0"/>
        </geometry>
        <material name="body"/>
      </visual>
      <visual name="visual_leg1_lower">
        <origin xyz="0.2 0 0" rpy="-1.5708 0 0"/>
        <geometry>
          <mesh filename="../meshes/obj/lower_leg.obj" scale="1.0 1.0 1.0"/>
        </geometry>
        <material name="lower_leg"/>
      </visual>
      <collision name="collision_leg1_foot">
        <origin xyz="0.4 0 0" rpy="-1.5708 0 0"/>
        <geometry>
          <sphere radius="0.06"/>
        </geometry>
      </collision>
      <collision name="collision_leg1_lower">
        <origin xyz="0.16695 0 0" rpy="-1.5708 0 0"/>
        <geometry>
          <box size="0.27958 0.06 0.06"/>
        </geometry>
      </collision>
    </link>

    <link name="leg21">
    </link>

    <link name="leg22">
      <inertial>
        <origin xyz="0.15 0 0" rpy="0 0 0"/>
        <mass value="0.5"/>
        <inertia ixx="0.00024" ixy="-3e-05" ixz="4e-05" iyy="0.00514" iyz="0" izz="0.00515"/>
      </inertial>
      <visual name="visual_leg2_upper">
        <origin xyz="0.15 0 0" rpy="-1.5708 0 0"/>
        <geometry>
          <mesh filename="../meshes/obj/upper_leg.obj" scale="1.0 1.0 1.0"/>
        </geometry>
        <material name="upper_leg"/>
      </visual>
      <collision name="collision_leg2_upper">
        <origin xyz="0.12867 0 0" rpy="-1.5708 0 0"/>
        <geometry>
          <box size="0.23617 0.06 0.06"/>
        </geometry>
      </collision>
    </link>

    <link name="leg23">
      <inertial>
        <origin xyz="0.16667 0 -0.00809" rpy="0 0 0"/>
        <mass value="0.6"/>
        <inertia ixx="0.00066" ixy="0" ixz="-0.00081" iyy="0.01024" iyz="0" izz="0.00988"/>
      </inertial>
      <visual name="visual_leg2_foot">
        <origin xyz="0.4 0 0" rpy="-1.5708 0 1.5708"/>
        <geometry>
          <mesh filename="../meshes/obj/foot.obj" scale="1.0 1.0 1.0"/>
        </geometry>
        <material name="body"/>
      </visual>
      <visual name="visual_leg2_knee">
        <origin xyz="5e-05 -4e-05 -0.04856" rpy="1.5708 0 0"/>
        <geometry>
          <mesh filename="../meshes/obj/knee.obj" scale="1.0 1.0 1.0"/>
        </geometry>
        <material name="body"/>
      </visual>
      <visual name="visual_leg2_lower">
        <origin xyz="0.2 0 0" rpy="-1.5708 0 0"/>
        <geometry>
          <mesh filename="../meshes/obj/lower_leg.obj" scale="1.0 1.0 1.0"/>
        </geometry>
        <material name="lower_leg"/>
      </visual>
      <collision name="collision_leg2_foot">
        <origin xyz="0.4 0 0" rpy="-1.5708 0 0"/>
        <geometry>
          <sphere radius="0.06"/>
        </geometry>
      </collision>
      <collision name="collision_leg2_lower">
        <origin xyz="0.16695 0 0" rpy="-1.5708 0 0"/>
        <geometry>
          <box size="0.27958 0.06 0.06"/>
        </geometry>
      </collision>
    </link>

    <link name="leg31">
    </link>

    <link name="leg32">
      <inertial>
        <origin xyz="0.15 0 0" rpy="0 0 0"/>
        <mass value="0.5"/>
        <inertia ixx="0.00024" ixy="-3e-05" ixz="4e-05" iyy="0.00514" iyz="0" izz="0.00515"/>
      </inertial>
      <visual name="visual_leg3_upper">
        <origin xyz="0.15 0 0" rpy="-1.5708 0 0"/>
        <geometry>
          <mesh filename="../meshes/obj/upper_leg.obj" scale="1.0 1.0 1.0"/>
        </geometry>
        <material name="upper_leg"/>
      </visual>
      <collision name="collision_leg3_upper">
        <origin xyz="0.12867 0 0" rpy="-1.5708 0 0"/>
        <geometry>
          <box size="0.23617 0.06 0.06"/>
        </geometry>
      </collision>
    </link>

    <link name="leg33">
      <inertial>
        <origin xyz="0.16666 0 -0.00847" rpy="0 0 0"/>
        <mass value="0.6"/>
        <inertia ixx="0.00052" ixy="0" ixz="-0.00085" iyy="0.01026" iyz="0" izz="0.01004"/>
      </inertial>
      <visual name="visual_leg3_foot">
        <origin xyz="0.4 0 0" rpy="-1.5708 0 1.5708"/>
        <geometry>
          <mesh filename="../meshes/obj/foot.obj" scale="1.0 1.0 1.0"/>
        </geometry>
        <material name="body"/>
      </visual>
      <visual name="visual_leg3_knee">
        <origin xyz="-6e-05 2e-05 -0.05082" rpy="1.5708 0 -1.5708"/>
        <geometry>
          <mesh filename="../meshes/obj/knee.obj" scale="1.0 1.0 1.0"/>
        </geometry>
        <material name="body"/>
      </visual>
      <visual name="visual_leg3_lower">
        <origin xyz="0.2 0 0" rpy="-1.5708 0 0"/>
        <geometry>
          <mesh filename="../meshes/obj/lower_leg.obj" scale="1.0 1.0 1.0"/>
        </geometry>
        <material name="lower_leg"/>
      </visual>
      <collision name="collision_leg3_foot">
        <origin xyz="0.4 0 0" rpy="-1.5708 0 0"/>
        <geometry>
          <sphere radius="0.06"/>
        </geometry>
      </collision>
      <collision name="collision_leg3_lower">
        <origin xyz="0.16695 0 0" rpy="-1.5708 0 0"/>
        <geometry>
          <box size="0.27958 0.06 0.06"/>
        </geometry>
      </collision>
    </link>

    <link name="leg41">
    </link>

    <link name="leg42">
      <inertial>
        <origin xyz="0.15 0 0" rpy="0 0 0"/>
        <mass value="0.5"/>
        <inertia ixx="0.00024" ixy="-3e-05" ixz="4e-05" iyy="0.00514" iyz="0" izz="0.00515"/>
      </inertial>
      <visual name="visual_leg4_upper">
        <origin xyz="0.15 0 0" rpy="-1.5708 0 0"/>
        <geometry>
          <mesh filename="../meshes/obj/upper_leg.obj" scale="1.0 1.0 1.0"/>
        </geometry>
        <material name="upper_leg"/>
      </visual>
      <collision name="collision_leg4_upper">
        <origin xyz="0.12867 0 0" rpy="-1.5708 0 0"/>
        <geometry>
          <box size="0.23617 0.06 0.06"/>
        </geometry>
      </collision>
    </link>

    <link name="leg43">
      <inertial>
        <origin xyz="0.16669 -2e-05 -0.00761" rpy="0 0 0"/>
        <mass value="0.6"/>
        <inertia ixx="0.00048" ixy="0" ixz="-0.00076" iyy="0.01021" iyz="0" izz="0.01004"/>
      </inertial>
      <visual name="visual_leg4_foot">
        <origin xyz="0.4 0 0" rpy="-1.5708 0 1.5708"/>
        <geometry>
          <mesh filename="../meshes/obj/foot.obj" scale="1.0 1.0 1.0"/>
        </geometry>
        <material name="body"/>
      </visual>
      <visual name="visual_leg4_knee">
        <origin xyz="0.00016 -0.00015 -0.04568" rpy="-1.5708 0 1.5708"/>
        <geometry>
          <mesh filename="../meshes/obj/knee.obj" scale="1.0 1.0 1.0"/>
        </geometry>
        <material name="body"/>
      </visual>
      <visual name="visual_leg4_lower">
        <origin xyz="0.2 0 0" rpy="-1.5708 0 0"/>
        <geometry>
          <mesh filename="../meshes/obj/lower_leg.obj" scale="1.0 1.0 1.0"/>
        </geometry>
        <material name="lower_leg"/>
      </visual>
      <collision name="collision_leg4_foot">
        <origin xyz="0.4 0 0" rpy="-1.5708 0 0"/>
        <geometry>
          <sphere radius="0.06"/>
        </geometry>
      </collision>
      <collision name="collision_leg4_lower">
        <origin xyz="0.16695 0 0" rpy="-1.5708 0 0"/>
        <geometry>
          <box size="0.27958 0.06 0.06"/>
        </geometry>
      </collision>
    </link>

    <link name="leg51">
    </link>

    <link name="leg52">
      <inertial>
        <origin xyz="0.15 0 0" rpy="0 0 0"/>
        <mass value="0.5"/>
        <inertia ixx="0.00024" ixy="-4e-05" ixz="4e-05" iyy="0.00514" iyz="0" izz="0.00515"/>
      </inertial>
      <visual name="visual_leg5_upper">
        <origin xyz="0.15 0 0" rpy="-1.5708 0 0"/>
        <geometry>
          <mesh filename="../meshes/obj/upper_leg.obj" scale="1.0 1.0 1.0"/>
        </geometry>
        <material name="upper_leg"/>
      </visual>
      <collision name="collision_leg5_upper">
        <origin xyz="0.12867 0 0" rpy="-1.5708 0 0"/>
        <geometry>
          <box size="0.23617 0.06 0.06"/>
        </geometry>
      </collision>
    </link>

    <link name="leg53">
      <inertial>
        <origin xyz="0.16666 0 -0.00847" rpy="0 0 0"/>
        <mass value="0.6"/>
        <inertia ixx="0.00052" ixy="0" ixz="-0.00085" iyy="0.01026" iyz="0" izz="0.01004"/>
      </inertial>
      <visual name="visual_leg5_foot">
        <origin xyz="0.4 0 0" rpy="-1.5708 0 1.5708"/>
        <geometry>
          <mesh filename="../meshes/obj/foot.obj" scale="1.0 1.0 1.0"/>
        </geometry>
        <material name="body"/>
      </visual>
      <visual name="visual_leg5_knee">
        <origin xyz="-6e-05 -5e-05 -0.05082" rpy="1.57081 0 -1.5708"/>
        <geometry>
          <mesh filename="../meshes/obj/knee.obj" scale="1.0 1.0 1.0"/>
        </geometry>
        <material name="body"/>
      </visual>
      <visual name="visual_leg5_lower">
        <origin xyz="0.2 0 0" rpy="-1.5708 0 0"/>
        <geometry>
          <mesh filename="../meshes/obj/lower_leg.obj" scale="1.0 1.0 1.0"/>
        </geometry>
        <material name="lower_leg"/>
      </visual>
      <collision name="collision_leg5_foot">
        <origin xyz="0.4 0 0" rpy="-1.5708 0 0"/>
        <geometry>
          <sphere radius="0.06"/>
        </geometry>
      </collision>
      <collision name="collision_leg5_lower">
        <origin xyz="0.16695 0 0" rpy="-1.5708 0 0"/>
        <geometry>
          <box size="0.27958 0.06 0.06"/>
        </geometry>
      </collision>
    </link>

    <link name="leg61">
    </link>

    <link name="leg62">
      <inertial>
        <origin xyz="0.15 0 0" rpy="0 0 0"/>
        <mass value="0.5"/>
        <inertia ixx="0.00024" ixy="-3e-05" ixz="4e-05" iyy="0.00514" iyz="0" izz="0.00515"/>
      </inertial>
      <visual name="visual_leg6_upper">
        <origin xyz="0.15 0 0" rpy="-1.5708 0 0"/>
        <geometry>
          <mesh filename="../meshes/obj/upper_leg.obj" scale="1.0 1.0 1.0"/>
        </geometry>
        <material name="upper_leg"/>
      </visual>
      <collision name="collision_leg6_upper">
        <origin xyz="0.12867 0 0" rpy="-1.5708 0 0"/>
        <geometry>
          <box size="0.23617 0.06 0.06"/>
        </geometry>
      </collision>
    </link>

    <link name="leg63">
      <inertial>
        <origin xyz="0.16666 0 -0.00761" rpy="0 0 0"/>
        <mass value="0.6"/>
        <inertia ixx="0.00048" ixy="0" ixz="-0.00076" iyy="0.01022" iyz="0" izz="0.01004"/>
      </inertial>
      <visual name="visual_leg6_foot">
        <origin xyz="0.4 0 0" rpy="-1.5708 0 1.5708"/>
        <geometry>
          <mesh filename="../meshes/obj/foot.obj" scale="1.0 1.0 1.0"/>
        </geometry>
        <material name="body"/>
      </visual>
      <visual name="visual_leg6_knee">
        <origin xyz="-6e-05 -6e-05 -0.04568" rpy="-1.5708 0 1.5708"/>
        <geometry>
          <mesh filename="../meshes/obj/knee.obj" scale="1.0 1.0 1.0"/>
        </geometry>
        <material name="body"/>
      </visual>
      <visual name="visual_leg6_lower">
        <origin xyz="0.2 0 0" rpy="-1.5708 0 0"/>
        <geometry>
          <mesh filename="../meshes/obj/lower_leg.obj" scale="1.0 1.0 1.0"/>
        </geometry>
        <material name="lower_leg"/>
      </visual>
      <collision name="collision_leg6_foot">
        <origin xyz="0.4 0 0" rpy="-1.5708 0 0"/>
        <geometry>
          <sphere radius="0.06"/>
        </geometry>
      </collision>
      <collision name="collision_leg6_lower">
        <origin xyz="0.16695 0 0" rpy="-1.5708 0 0"/>
        <geometry>
          <box size="0.27958 0.06 0.06"/>
        </geometry>
      </collision>
    </link>

    <link name="link_velodyne">
      <inertial>
        <origin xyz="0 0 0" rpy="0 0 0"/>
        <mass value="2.0"/>
        <inertia ixx="0.00437" ixy="0" ixz="0" iyy="0.00437" iyz="0" izz="0.00182"/>
      </inertial>
      <visual name="visual_velodyne">
        <origin xyz="0 0 0" rpy="0 0 0"/>
        <geometry>
          <mesh filename="../meshes/obj/velodyne.obj" scale="1.0 1.0 1.0"/>
        </geometry>
        <material name="velodyne"/>
      </visual>
    </link>

    <link name="root">
      <inertial>
        <origin xyz="0.00889 0 0.0062" rpy="0 0 0"/>
        <mass value="18.5"/>
        <inertia ixx="1.32739" ixy="0" ixz="0.01866" iyy="2.62013" iyz="0" izz="2.63639"/>
      </inertial>
      <visual name="visual_body">
        <origin xyz="0 0 0" rpy="0 0 0"/>
        <geometry>
          <mesh filename="../meshes/obj/torso.obj" scale="1.0 1.0 1.0"/>
        </geometry>
        <material name="body"/>
      </visual>
      <visual name="visual_computing_unit">
        <origin xyz="-0.15392 0 0.05731" rpy="0 0 0"/>
        <geometry>
          <mesh filename="../meshes/obj/pc.obj" scale="0.08471 0.05027 0.02624"/>
        </geometry>
        <material name="upper_leg"/>
      </visual>
      <visual name="visual_head">
        <origin xyz="0.50773 0 0" rpy="0 0 1.5708"/>
        <geometry>
          <mesh filename="../meshes/obj/head.obj" scale="1.0 1.0 1.0"/>
        </geometry>
        <material name="body"/>
      </visual>
      <visual name="visual_hip1">
        <origin xyz="0.3 0 0" rpy="0 0 -1.5708"/>
        <geometry>
          <mesh filename="../meshes/obj/hip.obj" scale="1.0 1.0 1.0"/>
        </geometry>
        <material name="body"/>
      </visual>
      <visual name="visual_hip2">
        <origin xyz="0 0 0" rpy="0 0 -1.5708"/>
        <geometry>
          <mesh filename="../meshes/obj/hip.obj" scale="1.0 1.0 1.0"/>
        </geometry>
        <material name="body"/>
      </visual>
      <visual name="visual_hip3">
        <origin xyz="-0.3 0 0" rpy="0 0 -1.5708"/>
        <geometry>
          <mesh filename="../meshes/obj/hip.obj" scale="1.0 1.0 1.0"/>
        </geometry>
        <material name="body"/>
      </visual>
      <visual name="visual_neck">
        <origin xyz="0.4 0 0" rpy="0 0 0"/>
        <geometry>
          <mesh filename="../meshes/obj/neck.obj" scale="0.90762 0.7605 0.7605"/>
        </geometry>
        <material name="body"/>
      </visual>
      <collision name="collision_body">
        <origin xyz="0 0 0" rpy="0 0 0"/>
        <geometry>
          <box size="0.66 0.06 0.06"/>
        </geometry>
      </collision>
      <collision name="collision_head">
        <origin xyz="0.51233 0 0" rpy="0 0 1.5708"/>
        <geometry>
          <box size="0.22412 0.09 0.09"/>
        </geometry>
      </collision>
      <collision name="collision_neck">
        <origin xyz="0.39543 0 0" rpy="0 0 0"/>
        <geometry>
          <box size="0.09605 0.06 0.06"/>
        </geometry>
      </collision>
    </link>

    <joint name="leg11" type="revolute">
      <origin xyz="0.3 0.1 0" rpy="-1.5708 3.14159 0"/>
      <parent link="root"/>
      <child link="leg11"/>
      <axis xyz="0 -1.0 0"/>
      <limit lower="-3.14" upper="3.14" effort="60.0" velocity="3.14"/>
    </joint>

    <joint name="leg12" type="revolute">
      <origin xyz="0 0 0" rpy="0 0 1.5708"/>
      <parent link="leg11"/>
      <child link="leg12"/>
      <axis xyz="0 0 1.0"/>
      <limit lower="-3.14" upper="3.14" effort="60.0" velocity="3.14"/>
    </joint>

    <joint name="leg13" type="revolute">
      <origin xyz="0.3 0 0.1" rpy="0 0 -3.14159"/>
      <parent link="leg12"/>
      <child link="leg13"/>
      <axis xyz="0 0 1.0"/>
      <limit lower="-3.14" upper="3.14" effort="60.0" velocity="3.14"/>
    </joint>

    <joint name="leg21" type="revolute">
      <origin xyz="0.3 -0.1 0" rpy="1.5708 0 0"/>
      <parent link="root"/>
      <child link="leg21"/>
      <axis xyz="0 -1.0 0"/>
      <limit lower="-3.14" upper="3.14" effort="60.0" velocity="3.14"/>
    </joint>

    <joint name="leg22" type="revolute">
      <origin xyz="0 0 0" rpy="0 0 1.5708"/>
      <parent link="leg21"/>
      <child link="leg22"/>
      <axis xyz="0 0 1.0"/>
      <limit lower="-3.14" upper="3.14" effort="60.0" velocity="3.14"/>
    </joint>

    <joint name="leg23" type="revolute">
      <origin xyz="0.3 0 0.1" rpy="0 0 -3.14159"/>
      <parent link="leg22"/>
      <child link="leg23"/>
      <axis xyz="0 0 1.0"/>
      <limit lower="-3.14" upper="3.14" effort="60.0" velocity="3.14"/>
    </joint>

    <joint name="leg31" type="revolute">
      <origin xyz="0 0.1 0" rpy="-1.5708 3.14159 0"/>
      <parent link="root"/>
      <child link="leg31"/>
      <axis xyz="0 -1.0 0"/>
      <limit lower="-3.14" upper="3.14" effort="60.0" velocity="3.14"/>
    </joint>

    <joint name="leg32" type="revolute">
      <origin xyz="0 0 0" rpy="0 0 1.5708"/>
      <parent link="leg31"/>
      <child link="leg32"/>
      <axis xyz="0 0 1.0"/>
      <limit lower="-3.14" upper="3.14" effort="60.0" velocity="3.14"/>
    </joint>

    <joint name="leg33" type="revolute">
      <origin xyz="0.3 0 0.1" rpy="0 0 3.14159"/>
      <parent link="leg32"/>
      <child link="leg33"/>
      <axis xyz="0 0 1.0"/>
      <limit lower="-3.14" upper="3.14" effort="60.0" velocity="3.14"/>
    </joint>

    <joint name="leg41" type="revolute">
      <origin xyz="0 -0.1 0" rpy="1.5708 0 0"/>
      <parent link="root"/>
      <child link="leg41"/>
      <axis xyz="0 -1.0 0"/>
      <limit lower="-3.14" upper="3.14" effort="60.0" velocity="3.14"/>
    </joint>

    <joint name="leg42" type="revolute">
      <origin xyz="0 0 0" rpy="0 0 1.5708"/>
      <parent link="leg41"/>
      <child link="leg42"/>
      <axis xyz="0 0 1.0"/>
      <limit lower="-3.14" upper="3.14" effort="60.0" velocity="3.14"/>
    </joint>

    <joint name="leg43" type="revolute">
      <origin xyz="0.3 0 0.1" rpy="0 0 -3.14159"/>
      <parent link="leg42"/>
      <child link="leg43"/>
      <axis xyz="0 0 1.0"/>
      <limit lower="-3.14" upper="3.14" effort="60.0" velocity="3.14"/>
    </joint>

    <joint name="leg51" type="revolute">
      <origin xyz="-0.3 0.1 0" rpy="-1.5708 3.14159 0"/>
      <parent link="root"/>
      <child link="leg51"/>
      <axis xyz="0 -1.0 0"/>
      <limit lower="-3.14" upper="3.14" effort="60.0" velocity="3.14"/>
    </joint>

    <joint name="leg52" type="revolute">
      <origin xyz="0 0 0" rpy="0 0 1.5708"/>
      <parent link="leg51"/>
      <child link="leg52"/>
      <axis xyz="0 0 1.0"/>
      <limit lower="-3.14" upper="3.14" effort="60.0" velocity="3.14"/>
    </joint>

    <joint name="leg53" type="revolute">
      <origin xyz="0.3 0 0.1" rpy="0 0 -3.14158"/>
      <parent link="leg52"/>
      <child link="leg53"/>
      <axis xyz="0 0 1.0"/>
      <limit lower="-3.14" upper="3.14" effort="60.0" velocity="3.14"/>
    </joint>

    <joint name="leg61" type="revolute">
      <origin xyz="-0.3 -0.1 0" rpy="1.5708 0 0"/>
      <parent link="root"/>
      <child link="leg61"/>
      <axis xyz="0 -1.0 0"/>
      <limit lower="-3.14" upper="3.14" effort="60.0" velocity="3.14"/>
    </joint>

    <joint name="leg62" type="revolute">
      <origin xyz="0 0 0" rpy="0 0 1.5708"/>
      <parent link="leg61"/>
      <child link="leg62"/>
      <axis xyz="0 0 1.0"/>
      <limit lower="-3.14" upper="3.14" effort="60.0" velocity="3.14"/>
    </joint>

    <joint name="leg63" type="revolute">
      <origin xyz="0.3 0 0.1" rpy="0 0 -3.14159"/>
      <parent link="leg62"/>
      <child link="leg63"/>
      <axis xyz="0 0 1.0"/>
      <limit lower="-3.14" upper="3.14" effort="60.0" velocity="3.14"/>
    </joint>

    <joint name="link_velodyne" type="fixed">
      <origin xyz="0.5 0 0.11658" rpy="0 0 0"/>
      <parent link="root"/>
      <child link="link_velodyne"/>
    </joint>

    <material name="body">
      <color rgba="0.07902 0.10058 0.14757 1.0"/>
    </material>

    <material name="lower_leg">
      <color rgba="0.35052 0.51641 0.8 1.0"/>
    </material>

    <material name="upper_leg">
      <color rgba="0.10054 0.1863 0.34339 1.0"/>
    </material>

    <material name="velodyne">
      <color rgba="0.42216 0.42216 0.42216 1.0"/>
    </material>

  </robot>
